<sdf version='1.7'>
  <world name='default'>
    <light name='sun' type='directional'>
      <cast_shadows>1</cast_shadows>
      <pose>0 0 10 0 -0 0</pose>
      <diffuse>0.8 0.8 0.8 1</diffuse>
      <specular>0.2 0.2 0.2 1</specular>
      <attenuation>
        <range>1000</range>
        <constant>0.9</constant>
        <linear>0.01</linear>
        <quadratic>0.001</quadratic>
      </attenuation>
      <direction>-0.5 0.1 -0.9</direction>
      <spot>
        <inner_angle>0</inner_angle>
        <outer_angle>0</outer_angle>
        <falloff>0</falloff>
      </spot>
    </light>
    <model name='ground_plane'>
      <static>1</static>
      <link name='link'>
        <collision name='collision'>
          <geometry>
            <plane>
              <normal>0 0 1</normal>
              <size>100 100</size>
            </plane>
          </geometry>
          <surface>
            <contact>
              <collide_bitmask>65535</collide_bitmask>
              <ode/>
            </contact>
            <friction>
              <ode>
                <mu>100</mu>
                <mu2>50</mu2>
              </ode>
              <torsional>
                <ode/>
              </torsional>
            </friction>
            <bounce/>
          </surface>
          <max_contacts>10</max_contacts>
        </collision>
        <visual name='visual'>
          <cast_shadows>0</cast_shadows>
          <geometry>
            <plane>
              <normal>0 0 1</normal>
              <size>100 100</size>
            </plane>
          </geometry>
          <material>
            <script>
              <uri>file://media/materials/scripts/gazebo.material</uri>
              <name>Gazebo/Grey</name>
            </script>
          </material>
        </visual>
        <self_collide>0</self_collide>
        <enable_wind>0</enable_wind>
        <kinematic>0</kinematic>
      </link>
    </model>
    <gravity>0 0 -9.8</gravity>
    <magnetic_field>6e-06 2.3e-05 -4.2e-05</magnetic_field>
    <atmosphere type='adiabatic'/>
    <physics type='ode'>
      <max_step_size>0.001</max_step_size>
      <real_time_factor>1</real_time_factor>
      <real_time_update_rate>1000</real_time_update_rate>
    </physics>
    <scene>
      <ambient>0.4 0.4 0.4 1</ambient>
      <background>0.7 0.7 0.7 1</background>
      <shadows>1</shadows>
    </scene>
    <wind/>
    <spherical_coordinates>
      <surface_model>EARTH_WGS84</surface_model>
      <latitude_deg>0</latitude_deg>
      <longitude_deg>0</longitude_deg>
      <elevation>0</elevation>
      <heading_deg>0</heading_deg>
    </spherical_coordinates>
    <state world_name='default'>
      <sim_time>1489 384000000</sim_time>
      <real_time>465 211039960</real_time>
      <wall_time>1709581935 957426305</wall_time>
      <iterations>413863</iterations>
      <model name='ground_plane'>
        <pose>0 0 0 0 -0 0</pose>
        <scale>1 1 1</scale>
        <link name='link'>
          <pose>0 0 0 0 -0 0</pose>
          <velocity>0 0 0 0 -0 0</velocity>
          <acceleration>0 0 0 0 -0 0</acceleration>
          <wrench>0 0 0 0 -0 0</wrench>
        </link>
      </model>
      <model name='kinect'>
        <pose>1.43917 -0.535406 3.57354 3.14159 1.55728 3.14159</pose>
        <scale>1 1 1</scale>
        <link name='link'>
          <pose>1.43917 -0.535406 3.57354 3.14159 1.55728 3.14159</pose>
          <velocity>0 0 0 0 -0 0</velocity>
          <acceleration>0 0 0 0 -0 0</acceleration>
          <wrench>0 0 0 0 -0 0</wrench>
        </link>
      </model>
      <model name='robot_arm_urdf'>
        <pose>0 1e-06 -0 1e-06 -0 0</pose>
        <scale>1 1 1</scale>
        <link name='base_link'>
          <pose>1.3 0 0.764991 -1e-06 -0 -3.14119</pose>
          <velocity>-0 -0 0 0 1e-06 -1e-06</velocity>
          <acceleration>0.000241 -2e-06 -7e-06 -8.3e-05 0.011135 0.001057</acceleration>
          <wrench>0.004135 -2.7e-05 -0.000126 0 -0 0</wrench>
        </link>
        <link name='link_1'>
          <pose>1.3 2e-06 0.964991 1.5708 3e-06 -1.57036</pose>
          <velocity>-3e-06 -1e-06 0 -1e-06 5e-06 -2e-06</velocity>
          <acceleration>-0.023001 -0.0003 -2.5e-05 -0.000603 0.025087 0.010738</acceleration>
          <wrench>-0.071085 -0.000928 -7.6e-05 0 -0 0</wrench>
        </link>
        <link name='link_2'>
          <pose>1.3 2e-06 1.16999 1.5708 -0.000123 -1.57036</pose>
          <velocity>-4e-06 -1e-06 -0 -0.002574 -2e-05 2.9e-05</velocity>
          <acceleration>-0.051939 -0.000745 9e-05 0.002405 -0.010825 -0.192791</acceleration>
          <wrench>-0.290168 -0.00416 0.000502 0 -0 0</wrench>
        </link>
        <link name='link_3'>
          <pose>1.3 5.2e-05 1.56999 1.5708 0.000474 -1.57036</pose>
          <velocity>-2.2e-05 0.001029 -0 -0.002711 -3.8e-05 0.000127</velocity>
          <acceleration>-0.056825 -0.001274 0.001356 0.000737 -0.401994 -0.08972</acceleration>
          <wrench>-0.160598 -0.0036 0.003831 0 -0 0</wrench>
        </link>
        <link name='link_4'>
          <pose>1.29985 0.350052 1.57016 1.57252 -1.5687 -1.57208</pose>
          <velocity>-7.3e-05 0.001029 -0.000949 -0.003005 -3e-06 0.000154</velocity>
          <acceleration>-0.021702 -0.001034 0.002064 0.000879 -0.168565 -0.570638</acceleration>
          <wrench>-0.039274 -0.001871 0.003736 0 -0 0</wrench>
        </link>
        <link name='link_5'>
          <pose>1.29985 0.350447 1.38216 1.64125 -1.5687 -1.57212</pose>
          <velocity>-7.9e-05 0.000464 -0.00095 -0.003004 -3.3e-05 0.000156</velocity>
          <acceleration>0.015885 -0.00091 0.002118 -0.000127 -0.112086 -0.05834</acceleration>
          <wrench>0.003027 -0.000173 0.000404 0 -0 0</wrench>
        </link>
        <link name='link_6'>
          <pose>1.32748 -0.049731 1.92132 1.64131 -1.5687 -1.57218</pose>
          <velocity>7.4e-05 0.002089 0.00025 -0.003003 0.00014 0.000171</velocity>
          <acceleration>0.038612 -0.004286 0.007809 -0.068312 -0.477786 -0.425235</acceleration>
          <wrench>0.004499 -0.000499 0.00091 0 -0 0</wrench>
        </link>
        <link name='link_7'>
          <pose>1.27018 0.748216 1.92299 -1.49948 -1.5687 -1.57298</pose>
          <velocity>-9.9e-05 0.002088 -0.002147 -0.003009 6.5e-05 0.000161</velocity>
          <acceleration>0.029884 0.002384 -0.000915 0.032089 -0.307067 -0.346308</acceleration>
          <wrench>0.003482 0.000278 -0.000107 0 -0 0</wrench>
        </link>
      </model>
      <model name='robot_base'>
        <pose>1.32612 -0.027179 0 0 -0 0</pose>
        <scale>1 1 1</scale>
        <link name='link'>
          <pose>1.32612 -0.027179 0.73 0 -0 0</pose>
          <velocity>0 0 0 0 -0 0</velocity>
          <acceleration>0 0 0 0 -0 0</acceleration>
          <wrench>0 0 0 0 -0 0</wrench>
        </link>
      </model>
      <model name='table_new'>
        <pose>0.276393 -0.985835 0 0 -0 0</pose>
        <scale>1 1 1</scale>
        <link name='link'>
          <pose>0.276393 -0.985835 0 0 -0 0</pose>
          <velocity>0 0 0 0 -0 0</velocity>
          <acceleration>0 0 0 0 -0 0</acceleration>
          <wrench>0 0 0 0 -0 0</wrench>
        </link>
      </model>
      <model name='table_new_0'>
        <pose>2.31832 -0.03048 0 0 0 -1.56929</pose>
        <scale>1 1 1</scale>
        <link name='link'>
          <pose>2.31832 -0.03048 0 0 0 -1.56929</pose>
          <velocity>0 0 0 0 -0 0</velocity>
          <acceleration>0 0 0 0 -0 0</acceleration>
          <wrench>0 0 0 0 -0 0</wrench>
        </link>
      </model>
      <light name='sun'>
        <pose>0 0 10 0 -0 0</pose>
      </light>
    </state>
    <gui fullscreen='0'>
      <camera name='user_camera'>
        <pose>2.8704 -9.06476 4.68433 0 0.3818 1.61306</pose>
        <view_controller>orbit</view_controller>
        <projection_type>perspective</projection_type>
      </camera>
    </gui>
    <model name='robot_base'>
      <static>1</static>
      <link name='link'>
        <pose>0 0 0.73 0 -0 0</pose>
        <collision name='surface'>
          <pose>0 0 -0.015 0 -0 0</pose>
          <geometry>
            <box>
              <size>2.35 1 0.03</size>
            </box>
          </geometry>
          <max_contacts>10</max_contacts>
          <surface>
            <contact>
              <ode/>
            </contact>
            <bounce/>
            <friction>
              <torsional>
                <ode/>
              </torsional>
              <ode/>
            </friction>
          </surface>
        </collision>
        <visual name='visual'>
          <geometry>
            <mesh>
              <uri>model://robot_base/meshes/robot_base.dae</uri>
            </mesh>
          </geometry>
        </visual>
        <self_collide>0</self_collide>
        <enable_wind>0</enable_wind>
        <kinematic>0</kinematic>
      </link>
      <pose>0.735014 0.579936 0 0 -0 0</pose>
    </model>
    <model name='table_new'>
      <static>1</static>
      <link name='link'>
        <collision name='collision'>
          <geometry>
            <mesh>
              <uri>model://table_new/meshes/table_new.stl</uri>
              <scale>2 2 2</scale>
            </mesh>
          </geometry>
          <max_contacts>10</max_contacts>
          <surface>
            <contact>
              <ode/>
            </contact>
            <bounce/>
            <friction>
              <torsional>
                <ode/>
              </torsional>
              <ode/>
            </friction>
          </surface>
        </collision>
        <visual name='visual'>
          <geometry>
            <mesh>
              <uri>model://table_new/meshes/table_new.stl</uri>
              <scale>2 2 2</scale>
            </mesh>
          </geometry>
        </visual>
        <self_collide>0</self_collide>
        <enable_wind>0</enable_wind>
        <kinematic>0</kinematic>
      </link>
      <pose>0.131787 -1.08166 0 0 -0 0</pose>
    </model>
    <model name='table_new_0'>
      <static>1</static>
      <link name='link'>
        <collision name='collision'>
          <geometry>
            <mesh>
              <uri>model://table_new/meshes/table_new.stl</uri>
              <scale>2 2 2</scale>
            </mesh>
          </geometry>
          <max_contacts>10</max_contacts>
          <surface>
            <contact>
              <ode/>
            </contact>
            <bounce/>
            <friction>
              <torsional>
                <ode/>
              </torsional>
              <ode/>
            </friction>
          </surface>
        </collision>
        <visual name='visual'>
          <geometry>
            <mesh>
              <uri>model://table_new/meshes/table_new.stl</uri>
              <scale>2 2 2</scale>
            </mesh>
          </geometry>
        </visual>
        <self_collide>0</self_collide>
        <enable_wind>0</enable_wind>
        <kinematic>0</kinematic>
      </link>
      <pose>3.38987 -1.43209 0 0 -0 0</pose>
    </model>
    <model name='robot_arm_urdf'>
      <joint name='base_joint' type='fixed'>
        <pose relative_to='__model__'>1.3 0 0.764991 0 0 -3.14119</pose>
        <parent>world</parent>
        <child>base_link</child>
      </joint>
      <link name='base_link'>
        <pose relative_to='base_joint'>0 0 0 0 -0 0</pose>
        <inertial>
          <pose>0 0 0.073876 0 -0 0</pose>
          <mass>17.147</mass>
          <inertia>
            <ixx>0.192</ixx>
            <ixy>-4.9423e-10</ixy>
            <ixz>1.2752e-17</ixz>
            <iyy>0.192</iyy>
            <iyz>2.6417e-18</iyz>
            <izz>0.29544</izz>
          </inertia>
        </inertial>
        <collision name='base_link_collision'>
          <pose>0 0 0 0 -0 0</pose>
          <geometry>
            <mesh>
              <scale>1 1 1</scale>
              <uri>/home/elisa/ws_moveit/src/robot_arm_urdf/meshes/base_link.STL</uri>
            </mesh>
          </geometry>
          <max_contacts>10</max_contacts>
          <surface>
            <contact>
              <ode/>
            </contact>
            <bounce/>
            <friction>
              <torsional>
                <ode/>
              </torsional>
              <ode/>
            </friction>
          </surface>
        </collision>
        <visual name='base_link_visual'>
          <pose>0 0 0 0 -0 0</pose>
          <geometry>
            <mesh>
              <scale>1 1 1</scale>
              <uri>/home/elisa/ws_moveit/src/robot_arm_urdf/meshes/base_link.STL</uri>
            </mesh>
          </geometry>
        </visual>
        <self_collide>0</self_collide>
        <enable_wind>0</enable_wind>
        <kinematic>0</kinematic>
      </link>
      <joint name='joint_1' type='revolute'>
        <pose relative_to='base_link'>0 0 0.2 1.5708 -0 1.5708</pose>
        <parent>base_link</parent>
        <child>link_1</child>
        <axis>
          <xyz>0 1 0</xyz>
          <limit>
            <lower>0</lower>
            <upper>6.284</upper>
            <effort>300</effort>
            <velocity>3</velocity>
          </limit>
          <dynamics>
            <spring_reference>0</spring_reference>
            <spring_stiffness>0</spring_stiffness>
          </dynamics>
        </axis>
      </joint>
      <link name='link_1'>
        <pose relative_to='joint_1'>0 0 0 0 -0 0</pose>
        <inertial>
          <pose>-0 0.11047 -0 0 -0 0</pose>
          <mass>3.0905</mass>
          <inertia>
            <ixx>0.026302</ixx>
            <ixy>-2.5267e-15</ixy>
            <ixz>-1.4177e-12</ixz>
            <iyy>0.019632</iyy>
            <iyz>-7.4535e-12</iyz>
            <izz>0.025388</izz>
          </inertia>
        </inertial>
        <collision name='link_1_collision'>
          <pose>0 0 0 0 -0 0</pose>
          <geometry>
            <mesh>
              <scale>1 1 1</scale>
              <uri>/home/elisa/ws_moveit/src/robot_arm_urdf/meshes/link_1.STL</uri>
            </mesh>
          </geometry>
          <surface>
            <contact>
              <ode/>
            </contact>
            <friction>
              <ode/>
              <torsional>
                <ode/>
              </torsional>
            </friction>
            <bounce/>
          </surface>
          <max_contacts>10</max_contacts>
        </collision>
        <visual name='link_1_visual'>
          <pose>0 0 0 0 -0 0</pose>
          <geometry>
            <mesh>
              <scale>1 1 1</scale>
              <uri>/home/elisa/ws_moveit/src/robot_arm_urdf/meshes/link_1.STL</uri>
            </mesh>
          </geometry>
        </visual>
        <self_collide>1</self_collide>
        <enable_wind>0</enable_wind>
        <kinematic>0</kinematic>
      </link>
      <joint name='joint_2' type='revolute'>
        <pose relative_to='link_1'>0 0.205 0 0 -0 0</pose>
        <parent>link_1</parent>
        <child>link_2</child>
        <axis>
          <xyz>0 0 1</xyz>
          <limit>
            <lower>-1.57</lower>
            <upper>1.57</upper>
            <effort>200</effort>
            <velocity>3</velocity>
          </limit>
          <dynamics>
            <spring_reference>0</spring_reference>
            <spring_stiffness>0</spring_stiffness>
          </dynamics>
        </axis>
      </joint>
      <link name='link_2'>
        <pose relative_to='joint_2'>0 0 0 0 -0 0</pose>
        <inertial>
          <pose>-0 0.16752 -0 0 -0 0</pose>
          <mass>5.5867</mass>
          <inertia>
            <ixx>0.12632</ixx>
            <ixy>8.4877e-17</ixy>
            <ixz>7.8685e-19</ixz>
            <iyy>0.011401</iyy>
            <iyz>1.4432e-16</iyz>
            <izz>0.12911</izz>
          </inertia>
        </inertial>
        <collision name='link_2_collision'>
          <pose>0 0 0 0 -0 0</pose>
          <geometry>
            <mesh>
              <scale>1 1 1</scale>
              <uri>/home/elisa/ws_moveit/src/robot_arm_urdf/meshes/link_2.STL</uri>
            </mesh>
          </geometry>
          <surface>
            <contact>
              <ode/>
            </contact>
            <friction>
              <ode/>
              <torsional>
                <ode/>
              </torsional>
            </friction>
            <bounce/>
          </surface>
          <max_contacts>10</max_contacts>
        </collision>
        <visual name='link_2_visual'>
          <pose>0 0 0 0 -0 0</pose>
          <geometry>
            <mesh>
              <scale>1 1 1</scale>
              <uri>/home/elisa/ws_moveit/src/robot_arm_urdf/meshes/link_2.STL</uri>
            </mesh>
          </geometry>
        </visual>
        <self_collide>1</self_collide>
        <enable_wind>0</enable_wind>
        <kinematic>0</kinematic>
      </link>
      <joint name='joint_3' type='revolute'>
        <pose relative_to='link_2'>0 0.4 0 0 -0 0</pose>
        <parent>link_2</parent>
        <child>link_3</child>
        <axis>
          <xyz>0 0 1</xyz>
          <limit>
            <lower>-4.3284</lower>
            <upper>1.157</upper>
            <effort>200</effort>
            <velocity>3</velocity>
          </limit>
          <dynamics>
            <spring_reference>0</spring_reference>
            <spring_stiffness>0</spring_stiffness>
          </dynamics>
        </axis>
      </joint>
      <link name='link_3'>
        <pose relative_to='joint_3'>0 0 0 0 -0 0</pose>
        <inertial>
          <pose>-0.17893 0 -0 0 -0 0</pose>
          <mass>2.8262</mass>
          <inertia>
            <ixx>0.0074041</ixx>
            <ixy>-1.7927e-17</ixy>
            <ixz>4.2672e-17</ixz>
            <iyy>0.028552</iyy>
            <iyz>-3.4736e-10</iyz>
            <izz>0.025128</izz>
          </inertia>
        </inertial>
        <collision name='link_3_collision'>
          <pose>0 0 0 0 -0 0</pose>
          <geometry>
            <mesh>
              <scale>1 1 1</scale>
              <uri>/home/elisa/ws_moveit/src/robot_arm_urdf/meshes/link_3.STL</uri>
            </mesh>
          </geometry>
          <surface>
            <contact>
              <ode/>
            </contact>
            <friction>
              <ode/>
              <torsional>
                <ode/>
              </torsional>
            </friction>
            <bounce/>
          </surface>
          <max_contacts>10</max_contacts>
        </collision>
        <visual name='link_3_visual'>
          <pose>0 0 0 0 -0 0</pose>
          <geometry>
            <mesh>
              <scale>1 1 1</scale>
              <uri>/home/elisa/ws_moveit/src/robot_arm_urdf/meshes/link_3.STL</uri>
            </mesh>
          </geometry>
        </visual>
        <self_collide>1</self_collide>
        <enable_wind>0</enable_wind>
        <kinematic>0</kinematic>
      </link>
      <joint name='joint_4' type='revolute'>
        <pose relative_to='link_3'>-0.35 0 0 0 -0 1.5708</pose>
        <parent>link_3</parent>
        <child>link_4</child>
        <axis>
          <xyz>0 0 1</xyz>
          <limit>
            <lower>-3.142</lower>
            <upper>0</upper>
            <effort>200</effort>
            <velocity>3</velocity>
          </limit>
          <dynamics>
            <spring_reference>0</spring_reference>
            <spring_stiffness>0</spring_stiffness>
          </dynamics>
        </axis>
      </joint>
      <link name='link_4'>
        <pose relative_to='joint_4'>0 0 0 0 -0 0</pose>
        <inertial>
          <pose>-0.051672 -0 -0 0 -0 0</pose>
          <mass>1.8097</mass>
          <inertia>
            <ixx>0.0023112</ixx>
            <ixy>-9.6437e-18</ixy>
            <ixz>-9.9829e-19</ixz>
            <iyy>0.0096102</iyy>
            <iyz>1.3194e-19</iyz>
            <izz>0.0093908</izz>
          </inertia>
        </inertial>
        <collision name='link_4_collision'>
          <pose>0 0 0 0 -0 0</pose>
          <geometry>
            <mesh>
              <scale>1 1 1</scale>
              <uri>/home/elisa/ws_moveit/src/robot_arm_urdf/meshes/link_4.STL</uri>
            </mesh>
          </geometry>
          <surface>
            <contact>
              <ode/>
            </contact>
            <friction>
              <ode/>
              <torsional>
                <ode/>
              </torsional>
            </friction>
            <bounce/>
          </surface>
          <max_contacts>10</max_contacts>
        </collision>
        <visual name='link_4_visual'>
          <pose>0 0 0 0 -0 0</pose>
          <geometry>
            <mesh>
              <scale>1 1 1</scale>
              <uri>/home/elisa/ws_moveit/src/robot_arm_urdf/meshes/link_4.STL</uri>
            </mesh>
          </geometry>
        </visual>
        <self_collide>1</self_collide>
        <enable_wind>0</enable_wind>
        <kinematic>0</kinematic>
      </link>
      <joint name='joint_5' type='revolute'>
        <pose relative_to='link_4'>-0.188 0 0 0 -0 0</pose>
        <parent>link_4</parent>
        <child>link_5</child>
        <axis>
          <xyz>1 0 0</xyz>
          <limit>
            <lower>0</lower>
            <upper>3.142</upper>
            <effort>200</effort>
            <velocity>3</velocity>
          </limit>
          <dynamics>
            <spring_reference>0</spring_reference>
            <spring_stiffness>0</spring_stiffness>
          </dynamics>
        </axis>
      </joint>
      <link name='link_5'>
        <pose relative_to='joint_5'>0 0 0 0 -0 0</pose>
        <inertial>
          <pose>-0.018544 0 -0 0 -0 0</pose>
          <mass>0.19053</mass>
          <inertia>
            <ixx>0.00030197</ixx>
            <ixy>1.6611e-20</ixy>
            <ixz>3.6309e-21</ixz>
            <iyy>0.00022817</iyy>
            <iyz>-1.9664e-11</iyz>
            <izz>0.00011843</izz>
          </inertia>
        </inertial>
        <collision name='link_5_collision'>
          <pose>0 0 0 0 -0 0</pose>
          <geometry>
            <mesh>
              <scale>1 1 1</scale>
              <uri>/home/elisa/ws_moveit/src/robot_arm_urdf/meshes/link_5.STL</uri>
            </mesh>
          </geometry>
          <surface>
            <contact>
              <ode/>
            </contact>
            <friction>
              <ode/>
              <torsional>
                <ode/>
              </torsional>
            </friction>
            <bounce/>
          </surface>
          <max_contacts>10</max_contacts>
        </collision>
        <visual name='link_5_visual'>
          <pose>0 0 0 0 -0 0</pose>
          <geometry>
            <mesh>
              <scale>1 1 1</scale>
              <uri>/home/elisa/ws_moveit/src/robot_arm_urdf/meshes/link_5.STL</uri>
            </mesh>
          </geometry>
        </visual>
        <self_collide>1</self_collide>
        <enable_wind>0</enable_wind>
        <kinematic>0</kinematic>
      </link>
      <joint name='joint_6' type='prismatic'>
        <pose relative_to='link_5'>0.54 -0.4 0 0 -0 0</pose>
        <parent>link_5</parent>
        <child>link_6</child>
        <axis>
          <xyz>0 0 -1</xyz>
          <limit>
            <lower>0</lower>
            <upper>0.03</upper>
            <effort>100</effort>
            <velocity>3</velocity>
          </limit>
          <dynamics>
            <spring_reference>0</spring_reference>
            <spring_stiffness>0</spring_stiffness>
          </dynamics>
        </axis>
      </joint>
      <link name='link_6'>
        <pose relative_to='joint_6'>0 0 0 0 -0 0</pose>
        <inertial>
          <pose>-0.60237 0.4 -0.016013 0 -0 0</pose>
          <mass>0.11653</mass>
          <inertia>
            <ixx>3.9246e-05</ixx>
            <ixy>-9.4878e-20</ixy>
            <ixz>1.0258e-05</ixz>
            <iyy>7.1189e-05</iyy>
            <iyz>-3.4206e-20</iyz>
            <izz>8.4875e-05</izz>
          </inertia>
        </inertial>
        <collision name='link_6_collision'>
          <pose>0 0 0 0 -0 0</pose>
          <geometry>
            <mesh>
              <scale>1 1 1</scale>
              <uri>/home/elisa/ws_moveit/src/robot_arm_urdf/meshes/link_6.STL</uri>
            </mesh>
          </geometry>
          <surface>
            <contact>
              <ode/>
            </contact>
            <friction>
              <ode/>
              <torsional>
                <ode/>
              </torsional>
            </friction>
            <bounce/>
          </surface>
          <max_contacts>10</max_contacts>
        </collision>
        <visual name='link_6_visual'>
          <pose>0 0 0 0 -0 0</pose>
          <geometry>
            <mesh>
              <scale>1 1 1</scale>
              <uri>/home/elisa/ws_moveit/src/robot_arm_urdf/meshes/link_6.STL</uri>
            </mesh>
          </geometry>
        </visual>
        <self_collide>1</self_collide>
        <enable_wind>0</enable_wind>
        <kinematic>0</kinematic>
      </link>
      <joint name='joint_7' type='prismatic'>
        <pose relative_to='link_5'>0.54 0.4 0 -3.14159 0 0</pose>
        <parent>link_5</parent>
        <child>link_7</child>
        <axis>
          <xyz>0 0 1</xyz>
          <limit>
            <lower>-0.03</lower>
            <upper>0</upper>
            <effort>100</effort>
            <velocity>3</velocity>
          </limit>
          <dynamics>
            <spring_reference>0</spring_reference>
            <spring_stiffness>0</spring_stiffness>
          </dynamics>
        </axis>
      </joint>
      <link name='link_7'>
        <pose relative_to='joint_7'>0 0 0 0 -0 0</pose>
        <inertial>
          <pose>-0.60237 0.4 -0.016013 0 -0 0</pose>
          <mass>0.11653</mass>
          <inertia>
            <ixx>3.9246e-05</ixx>
            <ixy>-4.7946e-20</ixy>
            <ixz>1.0258e-05</ixz>
            <iyy>7.1189e-05</iyy>
            <iyz>-3.946e-20</iyz>
            <izz>8.4875e-05</izz>
          </inertia>
        </inertial>
        <collision name='link_7_collision'>
          <pose>0 0 0 0 -0 0</pose>
          <geometry>
            <mesh>
              <scale>1 1 1</scale>
              <uri>/home/elisa/ws_moveit/src/robot_arm_urdf/meshes/link_7.STL</uri>
            </mesh>
          </geometry>
          <surface>
            <contact>
              <ode/>
            </contact>
            <friction>
              <ode/>
              <torsional>
                <ode/>
              </torsional>
            </friction>
            <bounce/>
          </surface>
          <max_contacts>10</max_contacts>
        </collision>
        <visual name='link_7_visual'>
          <pose>0 0 0 0 -0 0</pose>
          <geometry>
            <mesh>
              <scale>1 1 1</scale>
              <uri>/home/elisa/ws_moveit/src/robot_arm_urdf/meshes/link_7.STL</uri>
            </mesh>
          </geometry>
        </visual>
        <self_collide>1</self_collide>
        <enable_wind>0</enable_wind>
        <kinematic>0</kinematic>
      </link>
      <static>0</static>
      <plugin name='control' filename='libgazebo_ros_control.so'>
        <robotNamespace>/</robotNamespace>
      </plugin>
      <pose>0 0 0 0 -0 0</pose>
    </model>
    <model name='kinect'>
      <pose>0.143937 1.22917 0.036 0 -0 0</pose>
      <link name='link'>
        <inertial>
          <mass>0.1</mass>
        </inertial>
        <collision name='collision'>
          <geometry>
            <box>
              <size>0.073 0.276 0.072</size>
            </box>
          </geometry>
          <max_contacts>10</max_contacts>
          <surface>
            <contact>
              <ode/>
            </contact>
            <bounce/>
            <friction>
              <torsional>
                <ode/>
              </torsional>
              <ode/>
            </friction>
          </surface>
        </collision>
        <visual name='visual'>
          <geometry>
            <mesh>
              <uri>model://kinect/meshes/kinect.dae</uri>
            </mesh>
          </geometry>
        </visual>
        <sensor name='camera' type='depth'>
          <update_rate>20</update_rate>
          <camera>
            <horizontal_fov>1.0472</horizontal_fov>
            <image>
              <width>640</width>
              <height>480</height>
              <format>R8G8B8</format>
            </image>
            <clip>
              <near>0.05</near>
              <far>3</far>
            </clip>
          </camera>
          <plugin name='camera_plugin' filename='libgazebo_ros_openni_kinect.so'>
            <baseline>0.2</baseline>
            <alwaysOn>1</alwaysOn>
            <updateRate>0.0</updateRate>
            <cameraName>camera_ir</cameraName>
            <imageTopicName>/camera/color/image_raw</imageTopicName>
            <cameraInfoTopicName>/camera/color/camera_info</cameraInfoTopicName>
            <depthImageTopicName>/camera/depth/image_raw</depthImageTopicName>
            <depthImageCameraInfoTopicName>/camera/depth/camera_info</depthImageCameraInfoTopicName>
            <pointCloudTopicName>/camera/depth/points</pointCloudTopicName>
            <frameName>camera_link</frameName>
            <pointCloudCutoff>0.5</pointCloudCutoff>
            <pointCloudCutoffMax>3.0</pointCloudCutoffMax>
            <distortionK1>0</distortionK1>
            <distortionK2>0</distortionK2>
            <distortionK3>0</distortionK3>
            <distortionT1>0</distortionT1>
            <distortionT2>0</distortionT2>
            <CxPrime>0</CxPrime>
            <Cx>0</Cx>
            <Cy>0</Cy>
            <focalLength>0</focalLength>
            <hackBaseline>0</hackBaseline>
          </plugin>
        </sensor>
        <self_collide>0</self_collide>
        <enable_wind>0</enable_wind>
        <kinematic>0</kinematic>
      </link>
      <static>1</static>
    </model>
  </world>
</sdf>
